Workbook

Sheet Juin
A1: ⏱ SUIVI DES HEURES – JUIN 2026
A2: Saisir les horaires dans les colonnes bleues | Journée de référence : 7h | 🔴 Mercredi semaine paire = non travaillé (-7h automatique) | I2: Prise de poste | J2: Début pause midi | K2: Fin pause midi | L2: Fin de poste | M2: Heures matin | N2: Heures après-midi | O2: Total heures | P2: Quota du jour | Q2: Heures sup
A3: 📅 Date | B3: Jour | C3: 🌅 Début matin | D3: 🍽️ Début pause | E3: 🔄 Reprise après-midi | F3: 🌆 Fin journée | G3: ⏱️ Total jour | H3: 🔥 Heures sup. (>7h)
A4: 46174 | B4: Lundi | C4: 0.28680556 | D4: 0.47916667 | E4: 0.52291667 | F4: 0.69791667 | G4: =IF(OR(C4="",D4="",E4="",F4=""),"",(D4-C4)+(F4-E4)) -> 0.36736111 | H4: =IF(G4="","",MAX(0,G4-TIME(7,0,0))) -> 0.075694444
A5: 46175 | B5: Mardi | C5: 0.29513889 | G5: =IF(OR(C5="",D5="",E5="",F5=""),"",(D5-C5)+(F5-E5)) | H5: =IF(G5="","",MAX(0,G5-TIME(7,0,0)))
A6: 46176 | B6: Mercredi | G6: -0.125 | H6: =IF(G6="","",MAX(0,G6-TIME(7,0,0))) -> 0
A7: 46177 | B7: Jeudi | G7: =IF(OR(C7="",D7="",E7="",F7=""),"",(D7-C7)+(F7-E7)) | H7: =IF(G7="","",MAX(0,G7-TIME(7,0,0)))
A8: 46178 | B8: Vendredi | G8: =IF(OR(C8="",D8="",E8="",F8=""),"",(D8-C8)+(F8-E8)) | H8: =IF(G8="","",MAX(0,G8-TIME(7,0,0)))
A9: 📊 Total – Semaine 1 | G9: =SUM(G4:G8) -> 0.24236111 | H9: =SUM(H4:H8) -> 0.075694444
A10: 46181 | B10: Lundi | G10: =IF(OR(C10="",D10="",E10="",F10=""),"",(D10-C10)+(F10-E10)) | H10: =IF(G10="","",MAX(0,G10-TIME(7,0,0)))
A11: 46182 | B11: Mardi | G11: =IF(OR(C11="",D11="",E11="",F11=""),"",(D11-C11)+(F11-E11)) | H11: =IF(G11="","",MAX(0,G11-TIME(7,0,0)))
A12: 46183 | B12: 🔴 Mercredi non travaillé – Déduction : -7h00 | G12: -7:00 | H12: —
A13: 46184 | B13: Jeudi | G13: =IF(OR(C13="",D13="",E13="",F13=""),"",(D13-C13)+(F13-E13)) | H13: =IF(G13="","",MAX(0,G13-TIME(7,0,0)))
A14: 46185 | B14: Vendredi | G14: =IF(OR(C14="",D14="",E14="",F14=""),"",(D14-C14)+(F14-E14)) | H14: =IF(G14="","",MAX(0,G14-TIME(7,0,0)))
A15: 📊 Total – Semaine 2 | G15: =SUM(G10:G14)-TIME(7,0,0) -> -0.29166667 | H15: =SUM(H10:H14) -> 0
A16: 46188 | B16: Lundi | G16: =IF(OR(C16="",D16="",E16="",F16=""),"",(D16-C16)+(F16-E16)) | H16: =IF(G16="","",MAX(0,G16-TIME(7,0,0)))
A17: 46189 | B17: Mardi | G17: =IF(OR(C17="",D17="",E17="",F17=""),"",(D17-C17)+(F17-E17)) | H17: =IF(G17="","",MAX(0,G17-TIME(7,0,0)))
A18: 46190 | B18: Mercredi | G18: =IF(OR(C18="",D18="",E18="",F18=""),"",(D18-C18)+(F18-E18)) | H18: =IF(G18="","",MAX(0,G18-TIME(7,0,0)))
A19: 46191 | B19: Jeudi | G19: =IF(OR(C19="",D19="",E19="",F19=""),"",(D19-C19)+(F19-E19)) | H19: =IF(G19="","",MAX(0,G19-TIME(7,0,0)))
A20: 46192 | B20: Vendredi | G20: =IF(OR(C20="",D20="",E20="",F20=""),"",(D20-C20)+(F20-E20)) | H20: =IF(G20="","",MAX(0,G20-TIME(7,0,0)))
A21: 📊 Total – Semaine 3 | G21: =SUM(G16:G20) -> 0 | H21: =SUM(H16:H20) -> 0
A22: 46195 | B22: Lundi | G22: =IF(OR(C22="",D22="",E22="",F22=""),"",(D22-C22)+(F22-E22)) | H22: =IF(G22="","",MAX(0,G22-TIME(7,0,0)))
A23: 46196 | B23: Mardi | G23: =IF(OR(C23="",D23="",E23="",F23=""),"",(D23-C23)+(F23-E23)) | H23: =IF(G23="","",MAX(0,G23-TIME(7,0,0)))
A24: 46197 | B24: 🔴 Mercredi non travaillé – Déduction : -7h00 | G24: -7:00 | H24: —
A25: 46198 | B25: Jeudi | G25: =IF(OR(C25="",D25="",E25="",F25=""),"",(D25-C25)+(F25-E25)) | H25: =IF(G25="","",MAX(0,G25-TIME(7,0,0)))
A26: 46199 | B26: Vendredi | G26: =IF(OR(C26="",D26="",E26="",F26=""),"",(D26-C26)+(F26-E26)) | H26: =IF(G26="","",MAX(0,G26-TIME(7,0,0)))
A27: 📊 Total – Semaine 4 | G27: =SUM(G22:G26)-TIME(7,0,0) -> -0.29166667 | H27: =SUM(H22:H26) -> 0
A28: 46202 | B28: Lundi | G28: =IF(OR(C28="",D28="",E28="",F28=""),"",(D28-C28)+(F28-E28)) | H28: =IF(G28="","",MAX(0,G28-TIME(7,0,0)))
A29: 46203 | B29: Mardi | G29: =IF(OR(C29="",D29="",E29="",F29=""),"",(D29-C29)+(F29-E29)) | H29: =IF(G29="","",MAX(0,G29-TIME(7,0,0)))
A30: 📊 Total – Semaine 5 | G30: =SUM(G28:G29) -> 0 | H30: =SUM(H28:H29) -> 0
A31: 📆 TOTAL MENSUEL – JUIN 2026 | G31: =G9+G15+G21+G27+G30 -> -0.34097222 | H31: =H9+H15+H21+H27+H30 -> 0.075694444
A32: 18/05/2026 | I32: 06:00 | J32: — | K32: — | L32: 17:00 | M32: 0 | N32: 0 | O32: 0 | P32: 7 | Q32: 0
A33: 19/05/2026 | I33: 06:00 | J33: — | K33: — | L33: 17:00 | M33: 0.20833333 | N33: 0.17708333 | O33: 0.38541667 | P33: 7 | Q33: 2.25
A34: 20/05/2026 | I34: 06:00 | J34: — | K34: — | L34: 17:00 | M34: 0.20833333 | N34: 0.17708333 | O34: 0.38541667 | P34: 7 | Q34: 2.25
A35: 21/05/2026 | I35: 06:00 | J35: — | K35: — | L35: 17:00 | M35: 0.20833333 | N35: 0.17708333 | O35: 0.38541667 | P35: 7 | Q35: 2.25
A36: 22/05/2026 | I36: 06:00 | J36: — | K36: — | L36: 17:00 | M36: 0.20833333 | N36: 0.17708333 | O36: 0.38541667 | P36: 7 | Q36: 2.25
A37: 25/05/2026 | I37: 06:00 | J37: — | K37: — | L37: 17:00 | M37: 0.20833333 | N37: 0.17708333 | O37: 0.38541667 | P37: 7 | Q37: 2.25
A38: 26/05/2026 | I38: 06:00 | J38: — | K38: — | L38: 17:00 | M38: 0.20833333 | N38: 0.17708333 | O38: 0.38541667 | P38: 7 | Q38: 2.25
A39: 27/05/2026 | I39: 06:00 | J39: — | K39: — | L39: 17:00 | M39: 0.20833333 | N39: 0.17708333 | O39: 0.38541667 | P39: -7 | Q39: 2.25
A40: 28/05/2026 | I40: 06:00 | J40: — | K40: — | L40: 17:00 | M40: 0.20833333 | N40: 0.17708333 | O40: 0.38541667 | P40: 7 | Q40: 2.25
...

Sheet Juillet
A1: ⏱ SUIVI DES HEURES – JUILLET 2026
A2: Saisir les horaires dans les colonnes bleues | Journée de référence : 7h | 🔴 Mercredi semaine paire = non travaillé (-7h automatique)
A3: 📅 Date | B3: Jour | C3: 🌅 Début matin | D3: 🍽️ Début pause | E3: 🔄 Reprise après-midi | F3: 🌆 Fin journée | G3: ⏱️ Total jour | H3: 🔥 Heures sup. (>7h)
A4: 46204 | B4: Mercredi | G4: =IF(OR(C4="",D4="",E4="",F4=""),"",(D4-C4)+(F4-E4)) | H4: =IF(G4="","",MAX(0,G4-TIME(7,0,0)))
A5: 46205 | B5: Jeudi | G5: =IF(OR(C5="",D5="",E5="",F5=""),"",(D5-C5)+(F5-E5)) | H5: =IF(G5="","",MAX(0,G5-TIME(7,0,0)))
A6: 46206 | B6: Vendredi | G6: =IF(OR(C6="",D6="",E6="",F6=""),"",(D6-C6)+(F6-E6)) | H6: =IF(G6="","",MAX(0,G6-TIME(7,0,0)))
A7: 📊 Total – Semaine 1 | G7: =SUM(G4:G6) -> 0 | H7: =SUM(H4:H6) -> 0
A8: 46209 | B8: Lundi | G8: =IF(OR(C8="",D8="",E8="",F8=""),"",(D8-C8)+(F8-E8)) | H8: =IF(G8="","",MAX(0,G8-TIME(7,0,0)))
A9: 46210 | B9: Mardi | G9: =IF(OR(C9="",D9="",E9="",F9=""),"",(D9-C9)+(F9-E9)) | H9: =IF(G9="","",MAX(0,G9-TIME(7,0,0)))
A10: 46211 | B10: 🔴 Mercredi non travaillé – Déduction : -7h00 | G10: -7:00 | H10: —
A11: 46212 | B11: Jeudi | G11: =IF(OR(C11="",D11="",E11="",F11=""),"",(D11-C11)+(F11-E11)) | H11: =IF(G11="","",MAX(0,G11-TIME(7,0,0)))
A12: 46213 | B12: Vendredi | G12: =IF(OR(C12="",D12="",E12="",F12=""),"",(D12-C12)+(F12-E12)) | H12: =IF(G12="","",MAX(0,G12-TIME(7,0,0)))
A13: 📊 Total – Semaine 2 | G13: =SUM(G8:G12)-TIME(7,0,0) -> -0.29166667 | H13: =SUM(H8:H12) -> 0
A14: 46216 | B14: Lundi | G14: =IF(OR(C14="",D14="",E14="",F14=""),"",(D14-C14)+(F14-E14)) | H14: =IF(G14="","",MAX(0,G14-TIME(7,0,0)))
A15: 46217 | B15: Mardi | G15: =IF(OR(C15="",D15="",E15="",F15=""),"",(D15-C15)+(F15-E15)) | H15: =IF(G15="","",MAX(0,G15-TIME(7,0,0)))
A16: 46218 | B16: Mercredi | G16: =IF(OR(C16="",D16="",E16="",F16=""),"",(D16-C16)+(F16-E16)) | H16: =IF(G16="","",MAX(0,G16-TIME(7,0,0)))
A17: 46219 | B17: Jeudi | G17: =IF(OR(C17="",D17="",E17="",F17=""),"",(D17-C17)+(F17-E17)) | H17: =IF(G17="","",MAX(0,G17-TIME(7,0,0)))
A18: 46220 | B18: Vendredi | G18: =IF(OR(C18="",D18="",E18="",F18=""),"",(D18-C18)+(F18-E18)) | H18: =IF(G18="","",MAX(0,G18-TIME(7,0,0)))
A19: 📊 Total – Semaine 3 | G19: =SUM(G14:G18) -> 0 | H19: =SUM(H14:H18) -> 0
A20: 46223 | B20: Lundi | G20: =IF(OR(C20="",D20="",E20="",F20=""),"",(D20-C20)+(F20-E20)) | H20: =IF(G20="","",MAX(0,G20-TIME(7,0,0)))
A21: 46224 | B21: Mardi | G21: =IF(OR(C21="",D21="",E21="",F21=""),"",(D21-C21)+(F21-E21)) | H21: =IF(G21="","",MAX(0,G21-TIME(7,0,0)))
A22: 46225 | B22: 🔴 Mercredi non travaillé – Déduction : -7h00 | G22: -7:00 | H22: —
A23: 46226 | B23: Jeudi | G23: =IF(OR(C23="",D23="",E23="",F23=""),"",(D23-C23)+(F23-E23)) | H23: =IF(G23="","",MAX(0,G23-TIME(7,0,0)))
A24: 46227 | B24: Vendredi | G24: =IF(OR(C24="",D24="",E24="",F24=""),"",(D24-C24)+(F24-E24)) | H24: =IF(G24="","",MAX(0,G24-TIME(7,0,0)))
A25: 📊 Total – Semaine 4 | G25: =SUM(G20:G24)-TIME(7,0,0) -> -0.29166667 | H25: =SUM(H20:H24) -> 0
A26: 46230 | B26: Lundi | G26: =IF(OR(C26="",D26="",E26="",F26=""),"",(D26-C26)+(F26-E26)) | H26: =IF(G26="","",MAX(0,G26-TIME(7,0,0)))
A27: 46231 | B27: Mardi | G27: =IF(OR(C27="",D27="",E27="",F27=""),"",(D27-C27)+(F27-E27)) | H27: =IF(G27="","",MAX(0,G27-TIME(7,0,0)))
A28: 46232 | B28: Mercredi | G28: =IF(OR(C28="",D28="",E28="",F28=""),"",(D28-C28)+(F28-E28)) | H28: =IF(G28="","",MAX(0,G28-TIME(7,0,0)))
A29: 46233 | B29: Jeudi | G29: =IF(OR(C29="",D29="",E29="",F29=""),"",(D29-C29)+(F29-E29)) | H29: =IF(G29="","",MAX(0,G29-TIME(7,0,0)))
A30: 46234 | B30: Vendredi | G30: =IF(OR(C30="",D30="",E30="",F30=""),"",(D30-C30)+(F30-E30)) | H30: =IF(G30="","",MAX(0,G30-TIME(7,0,0)))
A31: 📊 Total – Semaine 5 | G31: =SUM(G26:G30) -> 0 | H31: =SUM(H26:H30) -> 0
A32: 📆 TOTAL MENSUEL – JUILLET 2026 | G32: =G7+G13+G19+G25+G31 -> -0.58333333 | H32: =H7+H13+H19+H25+H31 -> 0
A34: 💡 Bleu = à saisir | Violet = total calculé | Jaune = heures sup. | 🔴 Rouge = mercredi non travaillé

Sheet Août
A1: ⏱ SUIVI DES HEURES – AOÛT 2026
A2: Saisir les horaires dans les colonnes bleues | Journée de référence : 7h | 🔴 Mercredi semaine paire = non travaillé (-7h automatique)
A3: 📅 Date | B3: Jour | C3: 🌅 Début matin | D3: 🍽️ Début pause | E3: 🔄 Reprise après-midi | F3: 🌆 Fin journée | G3: ⏱️ Total jour | H3: 🔥 Heures sup. (>7h)
A4: 46237 | B4: Lundi | G4: =IF(OR(C4="",D4="",E4="",F4=""),"",(D4-C4)+(F4-E4)) | H4: =IF(G4="","",MAX(0,G4-TIME(7,0,0)))
A5: 46238 | B5: Mardi | G5: =IF(OR(C5="",D5="",E5="",F5=""),"",(D5-C5)+(F5-E5)) | H5: =IF(G5="","",MAX(0,G5-TIME(7,0,0)))
A6: 46239 | B6: 🔴 Mercredi non travaillé – Déduction : -7h00 | G6: -7:00 | H6: —
A7: 46240 | B7: Jeudi | G7: =IF(OR(C7="",D7="",E7="",F7=""),"",(D7-C7)+(F7-E7)) | H7: =IF(G7="","",MAX(0,G7-TIME(7,0,0)))
A8: 46241 | B8: Vendredi | G8: =IF(OR(C8="",D8="",E8="",F8=""),"",(D8-C8)+(F8-E8)) | H8: =IF(G8="","",MAX(0,G8-TIME(7,0,0)))
A9: 📊 Total – Semaine 1 | G9: =SUM(G4:G8)-TIME(7,0,0) -> -0.29166667 | H9: =SUM(H4:H8) -> 0
A10: 46244 | B10: Lundi | G10: =IF(OR(C10="",D10="",E10="",F10=""),"",(D10-C10)+(F10-E10)) | H10: =IF(G10="","",MAX(0,G10-TIME(7,0,0)))
A11: 46245 | B11: Mardi | G11: =IF(OR(C11="",D11="",E11="",F11=""),"",(D11-C11)+(F11-E11)) | H11: =IF(G11="","",MAX(0,G11-TIME(7,0,0)))
A12: 46246 | B12: Mercredi | G12: =IF(OR(C12="",D12="",E12="",F12=""),"",(D12-C12)+(F12-E12)) | H12: =IF(G12="","",MAX(0,G12-TIME(7,0,0)))
A13: 46247 | B13: Jeudi | G13: =IF(OR(C13="",D13="",E13="",F13=""),"",(D13-C13)+(F13-E13)) | H13: =IF(G13="","",MAX(0,G13-TIME(7,0,0)))
A14: 46248 | B14: Vendredi | G14: =IF(OR(C14="",D14="",E14="",F14=""),"",(D14-C14)+(F14-E14)) | H14: =IF(G14="","",MAX(0,G14-TIME(7,0,0)))
A15: 📊 Total – Semaine 2 | G15: =SUM(G10:G14) -> 0 | H15: =SUM(H10:H14) -> 0
A16: 46251 | B16: Lundi | G16: =IF(OR(C16="",D16="",E16="",F16=""),"",(D16-C16)+(F16-E16)) | H16: =IF(G16="","",MAX(0,G16-TIME(7,0,0)))
A17: 46252 | B17: Mardi | G17: =IF(OR(C17="",D17="",E17="",F17=""),"",(D17-C17)+(F17-E17)) | H17: =IF(G17="","",MAX(0,G17-TIME(7,0,0)))
A18: 46253 | B18: 🔴 Mercredi non travaillé – Déduction : -7h00 | G18: -7:00 | H18: —
A19: 46254 | B19: Jeudi | G19: =IF(OR(C19="",D19="",E19="",F19=""),"",(D19-C19)+(F19-E19)) | H19: =IF(G19="","",MAX(0,G19-TIME(7,0,0)))
A20: 46255 | B20: Vendredi | G20: =IF(OR(C20="",D20="",E20="",F20=""),"",(D20-C20)+(F20-E20)) | H20: =IF(G20="","",MAX(0,G20-TIME(7,0,0)))
A21: 📊 Total – Semaine 3 | G21: =SUM(G16:G20)-TIME(7,0,0) -> -0.29166667 | H21: =SUM(H16:H20) -> 0
A22: 46258 | B22: Lundi | G22: =IF(OR(C22="",D22="",E22="",F22=""),"",(D22-C22)+(F22-E22)) | H22: =IF(G22="","",MAX(0,G22-TIME(7,0,0)))
A23: 46259 | B23: Mardi | G23: =IF(OR(C23="",D23="",E23="",F23=""),"",(D23-C23)+(F23-E23)) | H23: =IF(G23="","",MAX(0,G23-TIME(7,0,0)))
A24: 46260 | B24: Mercredi | G24: =IF(OR(C24="",D24="",E24="",F24=""),"",(D24-C24)+(F24-E24)) | H24: =IF(G24="","",MAX(0,G24-TIME(7,0,0)))
A25: 46261 | B25: Jeudi | G25: =IF(OR(C25="",D25="",E25="",F25=""),"",(D25-C25)+(F25-E25)) | H25: =IF(G25="","",MAX(0,G25-TIME(7,0,0)))
A26: 46262 | B26: Vendredi | G26: =IF(OR(C26="",D26="",E26="",F26=""),"",(D26-C26)+(F26-E26)) | H26: =IF(G26="","",MAX(0,G26-TIME(7,0,0)))
A27: 📊 Total – Semaine 4 | G27: =SUM(G22:G26) -> 0 | H27: =SUM(H22:H26) -> 0
A28: 46265 | B28: Lundi | G28: =IF(OR(C28="",D28="",E28="",F28=""),"",(D28-C28)+(F28-E28)) | H28: =IF(G28="","",MAX(0,G28-TIME(7,0,0)))
A29: 📊 Total – Semaine 5 | G29: =SUM(G28) -> 0 | H29: =SUM(H28) -> 0
A30: 📆 TOTAL MENSUEL – AOÛT 2026 | G30: =G9+G15+G21+G27+G29 -> -0.58333333 | H30: =H9+H15+H21+H27+H29 -> 0
A32: 💡 Bleu = à saisir | Violet = total calculé | Jaune = heures sup. | 🔴 Rouge = mercredi non travaillé

Sheet Septembre
A1: ⏱ SUIVI DES HEURES – SEPTEMBRE 2026
A2: Saisir les horaires dans les colonnes bleues | Journée de référence : 7h | 🔴 Mercredi semaine paire = non travaillé (-7h automatique)
A3: 📅 Date | B3: Jour | C3: 🌅 Début matin | D3: 🍽️ Début pause | E3: 🔄 Reprise après-midi | F3: 🌆 Fin journée | G3: ⏱️ Total jour | H3: 🔥 Heures sup. (>7h)
A4: 46266 | B4: Mardi | G4: =IF(OR(C4="",D4="",E4="",F4=""),"",(D4-C4)+(F4-E4)) | H4: =IF(G4="","",MAX(0,G4-TIME(7,0,0)))
A5: 46267 | B5: 🔴 Mercredi non travaillé – Déduction : -7h00 | G5: -7:00 | H5: —
A6: 46268 | B6: Jeudi | G6: =IF(OR(C6="",D6="",E6="",F6=""),"",(D6-C6)+(F6-E6)) | H6: =IF(G6="","",MAX(0,G6-TIME(7,0,0)))
A7: 46269 | B7: Vendredi | G7: =IF(OR(C7="",D7="",E7="",F7=""),"",(D7-C7)+(F7-E7)) | H7: =IF(G7="","",MAX(0,G7-TIME(7,0,0)))
A8: 📊 Total – Semaine 1 | G8: =SUM(G4:G7)-TIME(7,0,0) -> -0.29166667 | H8: =SUM(H4:H7) -> 0
A9: 46272 | B9: Lundi | G9: =IF(OR(C9="",D9="",E9="",F9=""),"",(D9-C9)+(F9-E9)) | H9: =IF(G9="","",MAX(0,G9-TIME(7,0,0)))
A10: 46273 | B10: Mardi | G10: =IF(OR(C10="",D10="",E10="",F10=""),"",(D10-C10)+(F10-E10)) | H10: =IF(G10="","",MAX(0,G10-TIME(7,0,0)))
A11: 46274 | B11: Mercredi | G11: =IF(OR(C11="",D11="",E11="",F11=""),"",(D11-C11)+(F11-E11)) | H11: =IF(G11="","",MAX(0,G11-TIME(7,0,0)))
A12: 46275 | B12: Jeudi | G12: =IF(OR(C12="",D12="",E12="",F12=""),"",(D12-C12)+(F12-E12)) | H12: =IF(G12="","",MAX(0,G12-TIME(7,0,0)))
A13: 46276 | B13: Vendredi | G13: =IF(OR(C13="",D13="",E13="",F13=""),"",(D13-C13)+(F13-E13)) | H13: =IF(G13="","",MAX(0,G13-TIME(7,0,0)))
A14: 📊 Total – Semaine 2 | G14: =SUM(G9:G13) -> 0 | H14: =SUM(H9:H13) -> 0
A15: 46279 | B15: Lundi | G15: =IF(OR(C15="",D15="",E15="",F15=""),"",(D15-C15)+(F15-E15)) | H15: =IF(G15="","",MAX(0,G15-TIME(7,0,0)))
A16: 46280 | B16: Mardi | G16: =IF(OR(C16="",D16="",E16="",F16=""),"",(D16-C16)+(F16-E16)) | H16: =IF(G16="","",MAX(0,G16-TIME(7,0,0)))
A17: 46281 | B17: 🔴 Mercredi non travaillé – Déduction : -7h00 | G17: -7:00 | H17: —
A18: 46282 | B18: Jeudi | G18: =IF(OR(C18="",D18="",E18="",F18=""),"",(D18-C18)+(F18-E18)) | H18: =IF(G18="","",MAX(0,G18-TIME(7,0,0)))
A19: 46283 | B19: Vendredi | G19: =IF(OR(C19="",D19="",E19="",F19=""),"",(D19-C19)+(F19-E19)) | H19: =IF(G19="","",MAX(0,G19-TIME(7,0,0)))
A20: 📊 Total – Semaine 3 | G20: =SUM(G15:G19)-TIME(7,0,0) -> -0.29166667 | H20: =SUM(H15:H19) -> 0
A21: 46286 | B21: Lundi | G21: =IF(OR(C21="",D21="",E21="",F21=""),"",(D21-C21)+(F21-E21)) | H21: =IF(G21="","",MAX(0,G21-TIME(7,0,0)))
A22: 46287 | B22: Mardi | G22: =IF(OR(C22="",D22="",E22="",F22=""),"",(D22-C22)+(F22-E22)) | H22: =IF(G22="","",MAX(0,G22-TIME(7,0,0)))
A23: 46288 | B23: Mercredi | G23: =IF(OR(C23="",D23="",E23="",F23=""),"",(D23-C23)+(F23-E23)) | H23: =IF(G23="","",MAX(0,G23-TIME(7,0,0)))
A24: 46289 | B24: Jeudi | G24: =IF(OR(C24="",D24="",E24="",F24=""),"",(D24-C24)+(F24-E24)) | H24: =IF(G24="","",MAX(0,G24-TIME(7,0,0)))
A25: 46290 | B25: Vendredi | G25: =IF(OR(C25="",D25="",E25="",F25=""),"",(D25-C25)+(F25-E25)) | H25: =IF(G25="","",MAX(0,G25-TIME(7,0,0)))
A26: 📊 Total – Semaine 4 | G26: =SUM(G21:G25) -> 0 | H26: =SUM(H21:H25) -> 0
A27: 46293 | B27: Lundi | G27: =IF(OR(C27="",D27="",E27="",F27=""),"",(D27-C27)+(F27-E27)) | H27: =IF(G27="","",MAX(0,G27-TIME(7,0,0)))
A28: 46294 | B28: Mardi | G28: =IF(OR(C28="",D28="",E28="",F28=""),"",(D28-C28)+(F28-E28)) | H28: =IF(G28="","",MAX(0,G28-TIME(7,0,0)))
A29: 46295 | B29: 🔴 Mercredi non travaillé – Déduction : -7h00 | G29: -7:00 | H29: —
A30: 📊 Total – Semaine 5 | G30: =SUM(G27:G29)-TIME(7,0,0) -> -0.29166667 | H30: =SUM(H27:H29) -> 0
A31: 📆 TOTAL MENSUEL – SEPTEMBRE 2026 | G31: =G8+G14+G20+G26+G30 -> -0.875 | H31: =H8+H14+H20+H26+H30 -> 0
A33: 💡 Bleu = à saisir | Violet = total calculé | Jaune = heures sup. | 🔴 Rouge = mercredi non travaillé

Sheet Octobre
A1: ⏱ SUIVI DES HEURES – OCTOBRE 2026
A2: Saisir les horaires dans les colonnes bleues | Journée de référence : 7h | 🔴 Mercredi semaine paire = non travaillé (-7h automatique)
A3: 📅 Date | B3: Jour | C3: 🌅 Début matin | D3: 🍽️ Début pause | E3: 🔄 Reprise après-midi | F3: 🌆 Fin journée | G3: ⏱️ Total jour | H3: 🔥 Heures sup. (>7h)
A4: 46296 | B4: Jeudi | G4: =IF(OR(C4="",D4="",E4="",F4=""),"",(D4-C4)+(F4-E4)) | H4: =IF(G4="","",MAX(0,G4-TIME(7,0,0)))
A5: 46297 | B5: Vendredi | G5: =IF(OR(C5="",D5="",E5="",F5=""),"",(D5-C5)+(F5-E5)) | H5: =IF(G5="","",MAX(0,G5-TIME(7,0,0)))
A6: 📊 Total – Semaine 1 | G6: =SUM(G4:G5) -> 0 | H6: =SUM(H4:H5) -> 0
A7: 46300 | B7: Lundi | G7: =IF(OR(C7="",D7="",E7="",F7=""),"",(D7-C7)+(F7-E7)) | H7: =IF(G7="","",MAX(0,G7-TIME(7,0,0)))
A8: 46301 | B8: Mardi | G8: =IF(OR(C8="",D8="",E8="",F8=""),"",(D8-C8)+(F8-E8)) | H8: =IF(G8="","",MAX(0,G8-TIME(7,0,0)))
A9: 46302 | B9: Mercredi | G9: =IF(OR(C9="",D9="",E9="",F9=""),"",(D9-C9)+(F9-E9)) | H9: =IF(G9="","",MAX(0,G9-TIME(7,0,0)))
A10: 46303 | B10: Jeudi | G10: =IF(OR(C10="",D10="",E10="",F10=""),"",(D10-C10)+(F10-E10)) | H10: =IF(G10="","",MAX(0,G10-TIME(7,0,0)))
A11: 46304 | B11: Vendredi | G11: =IF(OR(C11="",D11="",E11="",F11=""),"",(D11-C11)+(F11-E11)) | H11: =IF(G11="","",MAX(0,G11-TIME(7,0,0)))
A12: 📊 Total – Semaine 2 | G12: =SUM(G7:G11) -> 0 | H12: =SUM(H7:H11) -> 0
A13: 46307 | B13: Lundi | G13: =IF(OR(C13="",D13="",E13="",F13=""),"",(D13-C13)+(F13-E13)) | H13: =IF(G13="","",MAX(0,G13-TIME(7,0,0)))
A14: 46308 | B14: Mardi | G14: =IF(OR(C14="",D14="",E14="",F14=""),"",(D14-C14)+(F14-E14)) | H14: =IF(G14="","",MAX(0,G14-TIME(7,0,0)))
A15: 46309 | B15: 🔴 Mercredi non travaillé – Déduction : -7h00 | G15: -7:00 | H15: —
A16: 46310 | B16: Jeudi | G16: =IF(OR(C16="",D16="",E16="",F16=""),"",(D16-C16)+(F16-E16)) | H16: =IF(G16="","",MAX(0,G16-TIME(7,0,0)))
A17: 46311 | B17: Vendredi | G17: =IF(OR(C17="",D17="",E17="",F17=""),"",(D17-C17)+(F17-E17)) | H17: =IF(G17="","",MAX(0,G17-TIME(7,0,0)))
A18: 📊 Total – Semaine 3 | G18: =SUM(G13:G17)-TIME(7,0,0) -> -0.29166667 | H18: =SUM(H13:H17) -> 0
A19: 46314 | B19: Lundi | G19: =IF(OR(C19="",D19="",E19="",F19=""),"",(D19-C19)+(F19-E19)) | H19: =IF(G19="","",MAX(0,G19-TIME(7,0,0)))
A20: 46315 | B20: Mardi | G20: =IF(OR(C20="",D20="",E20="",F20=""),"",(D20-C20)+(F20-E20)) | H20: =IF(G20="","",MAX(0,G20-TIME(7,0,0)))
A21: 46316 | B21: Mercredi | G21: =IF(OR(C21="",D21="",E21="",F21=""),"",(D21-C21)+(F21-E21)) | H21: =IF(G21="","",MAX(0,G21-TIME(7,0,0)))
A22: 46317 | B22: Jeudi | G22: =IF(OR(C22="",D22="",E22="",F22=""),"",(D22-C22)+(F22-E22)) | H22: =IF(G22="","",MAX(0,G22-TIME(7,0,0)))
A23: 46318 | B23: Vendredi | G23: =IF(OR(C23="",D23="",E23="",F23=""),"",(D23-C23)+(F23-E23)) | H23: =IF(G23="","",MAX(0,G23-TIME(7,0,0)))
A24: 📊 Total – Semaine 4 | G24: =SUM(G19:G23) -> 0 | H24: =SUM(H19:H23) -> 0
A25: 46321 | B25: Lundi | G25: =IF(OR(C25="",D25="",E25="",F25=""),"",(D25-C25)+(F25-E25)) | H25: =IF(G25="","",MAX(0,G25-TIME(7,0,0)))
A26: 46322 | B26: Mardi | G26: =IF(OR(C26="",D26="",E26="",F26=""),"",(D26-C26)+(F26-E26)) | H26: =IF(G26="","",MAX(0,G26-TIME(7,0,0)))
A27: 46323 | B27: 🔴 Mercredi non travaillé – Déduction : -7h00 | G27: -7:00 | H27: —
A28: 46324 | B28: Jeudi | G28: =IF(OR(C28="",D28="",E28="",F28=""),"",(D28-C28)+(F28-E28)) | H28: =IF(G28="","",MAX(0,G28-TIME(7,0,0)))
A29: 46325 | B29: Vendredi | G29: =IF(OR(C29="",D29="",E29="",F29=""),"",(D29-C29)+(F29-E29)) | H29: =IF(G29="","",MAX(0,G29-TIME(7,0,0)))
A30: 📊 Total – Semaine 5 | G30: =SUM(G25:G29)-TIME(7,0,0) -> -0.29166667 | H30: =SUM(H25:H29) -> 0
A31: 📆 TOTAL MENSUEL – OCTOBRE 2026 | G31: =G6+G12+G18+G24+G30 -> -0.58333333 | H31: =H6+H12+H18+H24+H30 -> 0
A33: 💡 Bleu = à saisir | Violet = total calculé | Jaune = heures sup. | 🔴 Rouge = mercredi non travaillé

Sheet Novembre
A1: ⏱ SUIVI DES HEURES – NOVEMBRE 2026
A2: Saisir les horaires dans les colonnes bleues | Journée de référence : 7h | 🔴 Mercredi semaine paire = non travaillé (-7h automatique)
A3: 📅 Date | B3: Jour | C3: 🌅 Début matin | D3: 🍽️ Début pause | E3: 🔄 Reprise après-midi | F3: 🌆 Fin journée | G3: ⏱️ Total jour | H3: 🔥 Heures sup. (>7h)
A4: 46328 | B4: Lundi | G4: =IF(OR(C4="",D4="",E4="",F4=""),"",(D4-C4)+(F4-E4)) | H4: =IF(G4="","",MAX(0,G4-TIME(7,0,0)))
A5: 46329 | B5: Mardi | G5: =IF(OR(C5="",D5="",E5="",F5=""),"",(D5-C5)+(F5-E5)) | H5: =IF(G5="","",MAX(0,G5-TIME(7,0,0)))
A6: 46330 | B6: Mercredi | G6: =IF(OR(C6="",D6="",E6="",F6=""),"",(D6-C6)+(F6-E6)) | H6: =IF(G6="","",MAX(0,G6-TIME(7,0,0)))
A7: 46331 | B7: Jeudi | G7: =IF(OR(C7="",D7="",E7="",F7=""),"",(D7-C7)+(F7-E7)) | H7: =IF(G7="","",MAX(0,G7-TIME(7,0,0)))
A8: 46332 | B8: Vendredi | G8: =IF(OR(C8="",D8="",E8="",F8=""),"",(D8-C8)+(F8-E8)) | H8: =IF(G8="","",MAX(0,G8-TIME(7,0,0)))
A9: 📊 Total – Semaine 1 | G9: =SUM(G4:G8) -> 0 | H9: =SUM(H4:H8) -> 0
A10: 46335 | B10: Lundi | G10: =IF(OR(C10="",D10="",E10="",F10=""),"",(D10-C10)+(F10-E10)) | H10: =IF(G10="","",MAX(0,G10-TIME(7,0,0)))
A11: 46336 | B11: Mardi | G11: =IF(OR(C11="",D11="",E11="",F11=""),"",(D11-C11)+(F11-E11)) | H11: =IF(G11="","",MAX(0,G11-TIME(7,0,0)))
A12: 46337 | B12: 🔴 Mercredi non travaillé – Déduction : -7h00 | G12: -7:00 | H12: —
A13: 46338 | B13: Jeudi | G13: =IF(OR(C13="",D13="",E13="",F13=""),"",(D13-C13)+(F13-E13)) | H13: =IF(G13="","",MAX(0,G13-TIME(7,0,0)))
A14: 46339 | B14: Vendredi | G14: =IF(OR(C14="",D14="",E14="",F14=""),"",(D14-C14)+(F14-E14)) | H14: =IF(G14="","",MAX(0,G14-TIME(7,0,0)))
A15: 📊 Total – Semaine 2 | G15: =SUM(G10:G14)-TIME(7,0,0) -> -0.29166667 | H15: =SUM(H10:H14) -> 0
A16: 46342 | B16: Lundi | G16: =IF(OR(C16="",D16="",E16="",F16=""),"",(D16-C16)+(F16-E16)) | H16: =IF(G16="","",MAX(0,G16-TIME(7,0,0)))
A17: 46343 | B17: Mardi | G17: =IF(OR(C17="",D17="",E17="",F17=""),"",(D17-C17)+(F17-E17)) | H17: =IF(G17="","",MAX(0,G17-TIME(7,0,0)))
A18: 46344 | B18: Mercredi | G18: =IF(OR(C18="",D18="",E18="",F18=""),"",(D18-C18)+(F18-E18)) | H18: =IF(G18="","",MAX(0,G18-TIME(7,0,0)))
A19: 46345 | B19: Jeudi | G19: =IF(OR(C19="",D19="",E19="",F19=""),"",(D19-C19)+(F19-E19)) | H19: =IF(G19="","",MAX(0,G19-TIME(7,0,0)))
A20: 46346 | B20: Vendredi | G20: =IF(OR(C20="",D20="",E20="",F20=""),"",(D20-C20)+(F20-E20)) | H20: =IF(G20="","",MAX(0,G20-TIME(7,0,0)))
A21: 📊 Total – Semaine 3 | G21: =SUM(G16:G20) -> 0 | H21: =SUM(H16:H20) -> 0
A22: 46349 | B22: Lundi | G22: =IF(OR(C22="",D22="",E22="",F22=""),"",(D22-C22)+(F22-E22)) | H22: =IF(G22="","",MAX(0,G22-TIME(7,0,0)))
A23: 46350 | B23: Mardi | G23: =IF(OR(C23="",D23="",E23="",F23=""),"",(D23-C23)+(F23-E23)) | H23: =IF(G23="","",MAX(0,G23-TIME(7,0,0)))
A24: 46351 | B24: 🔴 Mercredi non travaillé – Déduction : -7h00 | G24: -7:00 | H24: —
A25: 46352 | B25: Jeudi | G25: =IF(OR(C25="",D25="",E25="",F25=""),"",(D25-C25)+(F25-E25)) | H25: =IF(G25="","",MAX(0,G25-TIME(7,0,0)))
A26: 46353 | B26: Vendredi | G26: =IF(OR(C26="",D26="",E26="",F26=""),"",(D26-C26)+(F26-E26)) | H26: =IF(G26="","",MAX(0,G26-TIME(7,0,0)))
A27: 📊 Total – Semaine 4 | G27: =SUM(G22:G26)-TIME(7,0,0) -> -0.29166667 | H27: =SUM(H22:H26) -> 0
A28: 46356 | B28: Lundi | G28: =IF(OR(C28="",D28="",E28="",F28=""),"",(D28-C28)+(F28-E28)) | H28: =IF(G28="","",MAX(0,G28-TIME(7,0,0)))
A29: 📊 Total – Semaine 5 | G29: =SUM(G28) -> 0 | H29: =SUM(H28) -> 0
A30: 📆 TOTAL MENSUEL – NOVEMBRE 2026 | G30: =G9+G15+G21+G27+G29 -> -0.58333333 | H30: =H9+H15+H21+H27+H29 -> 0
A32: 💡 Bleu = à saisir | Violet = total calculé | Jaune = heures sup. | 🔴 Rouge = mercredi non travaillé

Sheet Décembre
A1: ⏱ SUIVI DES HEURES – DÉCEMBRE 2026
A2: Saisir les horaires dans les colonnes bleues | Journée de référence : 7h | 🔴 Mercredi semaine paire = non travaillé (-7h automatique)
A3: 📅 Date | B3: Jour | C3: 🌅 Début matin | D3: 🍽️ Début pause | E3: 🔄 Reprise après-midi | F3: 🌆 Fin journée | G3: ⏱️ Total jour | H3: 🔥 Heures sup. (>7h)
A4: 46357 | B4: Mardi | G4: =IF(OR(C4="",D4="",E4="",F4=""),"",(D4-C4)+(F4-E4)) | H4: =IF(G4="","",MAX(0,G4-TIME(7,0,0)))
A5: 46358 | B5: Mercredi | G5: =IF(OR(C5="",D5="",E5="",F5=""),"",(D5-C5)+(F5-E5)) | H5: =IF(G5="","",MAX(0,G5-TIME(7,0,0)))
A6: 46359 | B6: Jeudi | G6: =IF(OR(C6="",D6="",E6="",F6=""),"",(D6-C6)+(F6-E6)) | H6: =IF(G6="","",MAX(0,G6-TIME(7,0,0)))
A7: 46360 | B7: Vendredi | G7: =IF(OR(C7="",D7="",E7="",F7=""),"",(D7-C7)+(F7-E7)) | H7: =IF(G7="","",MAX(0,G7-TIME(7,0,0)))
A8: 📊 Total – Semaine 1 | G8: =SUM(G4:G7) -> 0 | H8: =SUM(H4:H7) -> 0
A9: 46363 | B9: Lundi | G9: =IF(OR(C9="",D9="",E9="",F9=""),"",(D9-C9)+(F9-E9)) | H9: =IF(G9="","",MAX(0,G9-TIME(7,0,0)))
A10: 46364 | B10: Mardi | G10: =IF(OR(C10="",D10="",E10="",F10=""),"",(D10-C10)+(F10-E10)) | H10: =IF(G10="","",MAX(0,G10-TIME(7,0,0)))
A11: 46365 | B11: 🔴 Mercredi non travaillé – Déduction : -7h00 | G11: -7:00 | H11: —
A12: 46366 | B12: Jeudi | G12: =IF(OR(C12="",D12="",E12="",F12=""),"",(D12-C12)+(F12-E12)) | H12: =IF(G12="","",MAX(0,G12-TIME(7,0,0)))
A13: 46367 | B13: Vendredi | G13: =IF(OR(C13="",D13="",E13="",F13=""),"",(D13-C13)+(F13-E13)) | H13: =IF(G13="","",MAX(0,G13-TIME(7,0,0)))
A14: 📊 Total – Semaine 2 | G14: =SUM(G9:G13)-TIME(7,0,0) -> -0.29166667 | H14: =SUM(H9:H13) -> 0
A15: 46370 | B15: Lundi | G15: =IF(OR(C15="",D15="",E15="",F15=""),"",(D15-C15)+(F15-E15)) | H15: =IF(G15="","",MAX(0,G15-TIME(7,0,0)))
A16: 46371 | B16: Mardi | G16: =IF(OR(C16="",D16="",E16="",F16=""),"",(D16-C16)+(F16-E16)) | H16: =IF(G16="","",MAX(0,G16-TIME(7,0,0)))
A17: 46372 | B17: Mercredi | G17: =IF(OR(C17="",D17="",E17="",F17=""),"",(D17-C17)+(F17-E17)) | H17: =IF(G17="","",MAX(0,G17-TIME(7,0,0)))
A18: 46373 | B18: Jeudi | G18: =IF(OR(C18="",D18="",E18="",F18=""),"",(D18-C18)+(F18-E18)) | H18: =IF(G18="","",MAX(0,G18-TIME(7,0,0)))
A19: 46374 | B19: Vendredi | G19: =IF(OR(C19="",D19="",E19="",F19=""),"",(D19-C19)+(F19-E19)) | H19: =IF(G19="","",MAX(0,G19-TIME(7,0,0)))
A20: 📊 Total – Semaine 3 | G20: =SUM(G15:G19) -> 0 | H20: =SUM(H15:H19) -> 0
A21: 46377 | B21: Lundi | G21: =IF(OR(C21="",D21="",E21="",F21=""),"",(D21-C21)+(F21-E21)) | H21: =IF(G21="","",MAX(0,G21-TIME(7,0,0)))
A22: 46378 | B22: Mardi | G22: =IF(OR(C22="",D22="",E22="",F22=""),"",(D22-C22)+(F22-E22)) | H22: =IF(G22="","",MAX(0,G22-TIME(7,0,0)))
A23: 46379 | B23: 🔴 Mercredi non travaillé – Déduction : -7h00 | G23: -7:00 | H23: —
A24: 46380 | B24: Jeudi | G24: =IF(OR(C24="",D24="",E24="",F24=""),"",(D24-C24)+(F24-E24)) | H24: =IF(G24="","",MAX(0,G24-TIME(7,0,0)))
A25: 46381 | B25: Vendredi | G25: =IF(OR(C25="",D25="",E25="",F25=""),"",(D25-C25)+(F25-E25)) | H25: =IF(G25="","",MAX(0,G25-TIME(7,0,0)))
A26: 📊 Total – Semaine 4 | G26: =SUM(G21:G25)-TIME(7,0,0) -> -0.29166667 | H26: =SUM(H21:H25) -> 0
A27: 46384 | B27: Lundi | G27: =IF(OR(C27="",D27="",E27="",F27=""),"",(D27-C27)+(F27-E27)) | H27: =IF(G27="","",MAX(0,G27-TIME(7,0,0)))
A28: 46385 | B28: Mardi | G28: =IF(OR(C28="",D28="",E28="",F28=""),"",(D28-C28)+(F28-E28)) | H28: =IF(G28="","",MAX(0,G28-TIME(7,0,0)))
A29: 46386 | B29: Mercredi | G29: =IF(OR(C29="",D29="",E29="",F29=""),"",(D29-C29)+(F29-E29)) | H29: =IF(G29="","",MAX(0,G29-TIME(7,0,0)))
A30: 46387 | B30: Jeudi | G30: =IF(OR(C30="",D30="",E30="",F30=""),"",(D30-C30)+(F30-E30)) | H30: =IF(G30="","",MAX(0,G30-TIME(7,0,0)))
A31: 📊 Total – Semaine 5 | G31: =SUM(G27:G30) -> 0 | H31: =SUM(H27:H30) -> 0
A32: 📆 TOTAL MENSUEL – DÉCEMBRE 2026 | G32: =G8+G14+G20+G26+G31 -> -0.58333333 | H32: =H8+H14+H20+H26+H31 -> 0
A34: 💡 Bleu = à saisir | Violet = total calculé | Jaune = heures sup. | 🔴 Rouge = mercredi non travaillé

Sheet 📊 Tableau de Bord
A1: 📊 TABLEAU DE BORD – SUIVI DES HEURES 2026
A2: Les données se mettent à jour automatiquement dès que vous saisissez vos heures
A4: 📈 RÉCAPITULATIF MENSUEL
A5: Mois | B5: Jours saisis | C5: Heures travaillées | D5: Heures sup. | E5: Moy. par jour | F5: Arrivée moyenne | G5: Départ moyen | H5: Pause moyenne
A6: Juin | B6: =COUNTIF(Juin!C4:C29,"<>") -> 2 | C6: =Juin!G31 -> -0.34097222 | D6: =Juin!H31 -> 0.075694444 | E6: =IFERROR(C6/B6,"") -> -0.17048611 | F6: =IFERROR(AVERAGEIF(Juin!C4:C29,"<>"),"") -> 0.29097222 | G6: =IFERROR(AVERAGEIF(Juin!F4:F29,"<>"),"") -> 0.69791667 | H6: =IFERROR(AVERAGEIF(Juin!E4:E29,"<>")-AVERAGEIF(Juin!D4:D29,"<>"),"") -> 0.04375 | I6: =IFERROR(C6*24,0) -> -8.1833333 | J6: =IFERROR(D6*24,0) -> 1.8166667
A7: Juillet | B7: =COUNTIF(Juillet!C4:C30,"<>") -> 0 | C7: =Juillet!G32 -> -0.58333333 | D7: =Juillet!H32 -> 0 | E7: =IFERROR(C7/B7,"") | F7: =IFERROR(AVERAGEIF(Juillet!C4:C30,"<>"),"") | G7: =IFERROR(AVERAGEIF(Juillet!F4:F30,"<>"),"") | H7: =IFERROR(AVERAGEIF(Juillet!E4:E30,"<>")-AVERAGEIF(Juillet!D4:D30,"<>"),"") | I7: =IFERROR(C7*24,0) -> -14 | J7: =IFERROR(D7*24,0) -> 0
A8: Août | B8: =COUNTIF('Août'!C4:C28,"<>") -> 0 | C8: ='Août'!G30 -> -0.58333333 | D8: ='Août'!H30 -> 0 | E8: =IFERROR(C8/B8,"") | F8: =IFERROR(AVERAGEIF('Août'!C4:C28,"<>"),"") | G8: =IFERROR(AVERAGEIF('Août'!F4:F28,"<>"),"") | H8: =IFERROR(AVERAGEIF('Août'!E4:E28,"<>")-AVERAGEIF('Août'!D4:D28,"<>"),"") | I8: =IFERROR(C8*24,0) -> -14 | J8: =IFERROR(D8*24,0) -> 0
A9: Septembre | B9: =COUNTIF(Septembre!C4:C29,"<>") -> 0 | C9: =Septembre!G31 -> -0.875 | D9: =Septembre!H31 -> 0 | E9: =IFERROR(C9/B9,"") | F9: =IFERROR(AVERAGEIF(Septembre!C4:C29,"<>"),"") | G9: =IFERROR(AVERAGEIF(Septembre!F4:F29,"<>"),"") | H9: =IFERROR(AVERAGEIF(Septembre!E4:E29,"<>")-AVERAGEIF(Septembre!D4:D29,"<>"),"") | I9: =IFERROR(C9*24,0) -> -21 | J9: =IFERROR(D9*24,0) -> 0
A10: Octobre | B10: =COUNTIF(Octobre!C4:C29,"<>") -> 0 | C10: =Octobre!G31 -> -0.58333333 | D10: =Octobre!H31 -> 0 | E10: =IFERROR(C10/B10,"") | F10: =IFERROR(AVERAGEIF(Octobre!C4:C29,"<>"),"") | G10: =IFERROR(AVERAGEIF(Octobre!F4:F29,"<>"),"") | H10: =IFERROR(AVERAGEIF(Octobre!E4:E29,"<>")-AVERAGEIF(Octobre!D4:D29,"<>"),"") | I10: =IFERROR(C10*24,0) -> -14 | J10: =IFERROR(D10*24,0) -> 0
A11: Novembre | B11: =COUNTIF(Novembre!C4:C28,"<>") -> 0 | C11: =Novembre!G30 -> -0.58333333 | D11: =Novembre!H30 -> 0 | E11: =IFERROR(C11/B11,"") | F11: =IFERROR(AVERAGEIF(Novembre!C4:C28,"<>"),"") | G11: =IFERROR(AVERAGEIF(Novembre!F4:F28,"<>"),"") | H11: =IFERROR(AVERAGEIF(Novembre!E4:E28,"<>")-AVERAGEIF(Novembre!D4:D28,"<>"),"") | I11: =IFERROR(C11*24,0) -> -14 | J11: =IFERROR(D11*24,0) -> 0
A12: Décembre | B12: =COUNTIF('Décembre'!C4:C30,"<>") -> 0 | C12: ='Décembre'!G32 -> -0.58333333 | D12: ='Décembre'!H32 -> 0 | E12: =IFERROR(C12/B12,"") | F12: =IFERROR(AVERAGEIF('Décembre'!C4:C30,"<>"),"") | G12: =IFERROR(AVERAGEIF('Décembre'!F4:F30,"<>"),"") | H12: =IFERROR(AVERAGEIF('Décembre'!E4:E30,"<>")-AVERAGEIF('Décembre'!D4:D30,"<>"),"") | I12: =IFERROR(C12*24,0) -> -14 | J12: =IFERROR(D12*24,0) -> 0
A13: 📆 TOTAL ANNUEL | B13: =SUM(B6:B12) -> 2 | C13: =SUM(C6:C12) -> -4.1326389 | D13: =SUM(D6:D12) -> 0.075694444 | E13: =IFERROR(C13/B13,"") -> -2.0663194 | F13: — | G13: — | H13: — | I13: =SUM(I6:I12) -> -99.183333 | J13: =SUM(J6:J12) -> 1.8166667
A15: 🏆 INDICATEURS CLÉS
A16: 🌅 Arrivée la plus fréquente | C16: 📊 Mois avec le + d'heures sup | E16: ⏱️ Meilleure semaine | G16: 📅 Jours saisis au total
A17: =IFERROR(TEXT(AVERAGEIF(Juin!C4:C100,"<>"),"HH:MM")&" (moy. juin)","—") -> 06:59 (moy. juin) | C17: {=IFERROR(INDEX(A6:A12,MATCH(MAX(D6:D12),D6:D12,0)),"—")} -> Juin | E17: "Voir feuille mensuelle" | G17: =IFERROR(B13&" jours","—") -> 2 jours
